Workbook

Sheet Dashboard
B1: REAL-TIME KPI PERFORMANCE DASHBOARD (2026)
B2: Name: Iqbal Fathi Izzudin | Division: Science Communication - BINUS Journal Staff
B4: AKTIVITAS BULANAN (Tugas Selesai)
B5: Bulan | C5: Desk Review (Total) | D5: Copy Edit (Total) | E5: Reviewing (Total)
B6: July | C6: =COUNTIF('KPI_9_Review Format'!O12:O200, "July") -> 15 | D6: =COUNTIF('KPI_8_Editing article'!O12:O200, "July") -> 8 | E6: =COUNTIF('KPI_10_Waktu review'!G12:G200, "July") -> 27
B7: August | C7: =COUNTIF('KPI_9_Review Format'!O12:O200, "August") -> 10 | D7: =COUNTIF('KPI_8_Editing article'!O12:O200, "August") -> 4 | E7: =COUNTIF('KPI_10_Waktu review'!G12:G200, "August") -> 9
B8: September | C8: =COUNTIF('KPI_9_Review Format'!O12:O200, "September") -> 4 | D8: =COUNTIF('KPI_8_Editing article'!O12:O200, "September") -> 4 | E8: =COUNTIF('KPI_10_Waktu review'!G12:G200, "September") -> 2
B9: October | C9: =COUNTIF('KPI_9_Review Format'!O12:O200, "October") -> 0 | D9: =COUNTIF('KPI_8_Editing article'!O12:O200, "October") -> 0 | E9: =COUNTIF('KPI_10_Waktu review'!G12:G200, "October") -> 0
B10: November | C10: =COUNTIF('KPI_9_Review Format'!O12:O200, "November") -> 0 | D10: =COUNTIF('KPI_8_Editing article'!O12:O200, "November") -> 0 | E10: =COUNTIF('KPI_10_Waktu review'!G12:G200, "November") -> 0
B11: December | C11: =COUNTIF('KPI_9_Review Format'!O12:O200, "December") -> 0 | D11: =COUNTIF('KPI_8_Editing article'!O12:O200, "December") -> 0 | E11: =COUNTIF('KPI_10_Waktu review'!G12:G200, "December") -> 0
B14: PENCAPAIAN KPI REAL-TIME
B15: No | C15: KPI Name | D15: Bobot (%) | E15: Target Capaian | F15: Capaian Saat Ini | G15: Skor (1-6) | H15: Nilai Akhir (Skor/4 * Bobot)
B16: 1 | C16: PI Unit Center | D16: 15 | E16: - | F16: ='KPI_1_PI Unit Center'!B4 -> 0 | G16: ='KPI_1_PI Unit Center'!B5 -> 0 | H16: =(G16/4)*(D16) -> 0
B17: 2 | C17: Pendataan Article Processing Charge (APC) | D17: 5 | E17: 100% penulis membayar APC | F17: ='KPI_2_Pendataan APC'!B4 -> 1 | G17: ='KPI_2_Pendataan APC'!B5 -> 4 | H17: =(G17/4)*(D17) -> 5
B18: 3 | C18: Enhancing OJS Website 7 Jurnal RTT | D18: 7.5 | E18: 50,00 - 74,99 | F18: ='KPI_3_Enhancing OJS'!B4 -> 0 | G18: ='KPI_3_Enhancing OJS'!B5 -> 0 | H18: =(G18/4)*(D18) -> 0
B19: 4 | C19: Penerapan Graphic Abstract pada artikel Binus Journal | D19: 5 | E19: 50,00 - 59,99 | F19: ='KPI_4_Graphic Abstrac'!B4 -> 0 | G19: ='KPI_4_Graphic Abstrac'!B5 -> 0 | H19: =(G19/4)*(D19) -> 0
B20: 5 | C20: Implementation of Scholarly Article Writing Competition | D20: 10 | E20: ≥ 30 participants | F20: ='KPI_5_Writing Competi'!B4 -> 0 | G20: ='KPI_5_Writing Competi'!B5 -> 0 | H20: =(G20/4)*(D20) -> 0
B21: 6 | C21: Student Commentary on Journal Binus | D21: 7.5 | E21: 50,00 - 59,00 | F21: ='KPI_6_Student Comment'!B4 -> 0 | G21: ='KPI_6_Student Comment'!B5 -> 0 | H21: =(G21/4)*(D21) -> 0
B22: 7 | C22: Support Binus Joint International Conference (ICOBAR) | D22: 10 | E22: 95.00 - 100.00% paper | F22: =KPI_7_ICOBAR!B4 -> 0 | G22: =KPI_7_ICOBAR!B5 -> 0 | H22: =(G22/4)*(D22) -> 0
B23: 8 | C23: Editing article | D23: 15 | E23: 4,00 - 4,00 | F23: ='KPI_8_Editing article'!B4 -> 0.215625 | G23: ='KPI_8_Editing article'!B5 -> 6 | H23: =(G23/4)*(D23) -> 22.5
B24: 9 | C24: Review Format Article | D24: 10 | E24: 2,00 - 2,99 | F24: ='KPI_9_Review Format'!B4 -> 0.043320106 | G24: ='KPI_9_Review Format'!B5 -> 6 | H24: =(G24/4)*(D24) -> 15
B25: 10 | C25: Waktu review artikel | D25: 10 | E25: 6,00 - 7,00 | F25: ='KPI_10_Waktu review'!B4 -> 1.8857143 | G25: ='KPI_10_Waktu review'!B5 -> 6 | H25: =(G25/4)*(D25) -> 15
B26: 11 | C26: Tugas Khusus | D26: 5 | E26: Minimum 3 tugas khusus (sesuai validasi VR RTT) diselesaikan | F26: ='KPI_11_Tugas Khusus'!B4 -> 0 | G26: ='KPI_11_Tugas Khusus'!B5 -> 0 | H26: =(G26/4)*(D26) -> 0
G27: TOTAL NILAI: | H27: =SUM(H16:H26) -> 57.5

Sheet KPI_1_PI Unit Center
A1: KPI 1: PI Unit Center
A2: Bobot: 15.0% | Target: -
A4: Capaian Saat Ini (Otomatis): | B4: 0 | C4: <-- Ketik manual persentase/capaian di sini
A5: Skor Saat Ini (1-6) (Otomatis): | B5: 0 | C5: <-- Ketik manual skor pencapaian (1-6) di sini
A7: Score 1 | B7: Score 2 | C7: Score 3 | D7: Score 4 | E7: Score 5 | F7: Score 6
A8: 0.00 - 3.49 | B8: - | C8: - | D8: - | E8: - | F8: 5.41 - 6.00

Sheet KPI_2_Pendataan APC
A1: KPI 2: Pendataan Article Processing Charge (APC)
A2: Bobot: 5.0% | Target: 100% penulis membayar APC
A4: Capaian Saat Ini (Otomatis): | B4: =IF(COUNTA(B12:B200)=0, 0, COUNTIF(D12:D200, "Diterima")/COUNTA(B12:B200)) -> 1
A5: Skor Saat Ini (1-6) (Otomatis): | B5: =IF(B4=1, 4, IF(B4>0, 1, 0)) -> 4
A7: Score 1 | B7: Score 2 | C7: Score 3 | D7: Score 4 | E7: Score 5 | F7: Score 6
A8: Ada penulis yang tidak bayar | B8: nan | C8: nan | D8: 100% penulis membayar APC | E8: nan | F8: Skor 4 + ada rekap
A10: ⬇️ INPUT DATA REALISASI DI SINI ⬇️
A11: No | B11: Submisi | C11: Jurnal | D11: Status APC | E11: Tanggal dikirim | F11: Bukti APC | G11: Month | H11: Nama Penulis
A12: 1 | B12: 14463 | C12: CT | D12: Diterima | E12: 46234 | F12: https://binusianorg.sharepoint.com/sites/BinusJurnal/Binus%20Jurnal/Binus%20Jurnal%20Publishing/26/COMTECH/APC/18.1/CT_1446.jpeg?csf=1&web=1&e=7b8Wik | G12: July
A13: 2 | B13: 14866 | C13: LC | D13: Diterima | E13: 46241 | F13: https://binusianorg.sharepoint.com/sites/BinusJurnal/Binus%20Jurnal/Binus%20Jurnal%20Publishing/26/LINGUA%20CULTURA/APC/21.1/LC_14866_APC.JPG?d=w9ace82bbb3da4763835e1c84ce49ad88&csf=1&web=1&e=JYLInr | G13: August | H13: Jessica Leony
A14: 3 | B14: 14145 | C14: CT | D14: Diterima | E14: 46244 | G14: August | H14: Fitri Agustina
A15: 4 | B15: 14976 | C15: CT | D15: Diterima | E15: 46262 | F15: https://binusianorg.sharepoint.com/sites/BinusJurnal/_layouts/15/guestaccess.aspx?share=IQAis1N3sr5hRqc4h_MZomMCAfbvEYWzb6jG7eJ56WZVAtA&e=e3SJDJ | G15: August
A16: 5 | B16: 15568 | C16: LC | D16: Diterima | E16: 46262 | F16: LC_15568_APC.jpg | G16: August | H16: Amelia Yuli Astuti
A17: 6 | B17: 14935 | C17: HM | D17: Diterima | E17: 46265 | F17: HM_14935_APC.pdf | G17: August | H17: Lely Surya Wardani
A18: 7 | B18: 14518 | C18: HM | D18: Diterima | E18: 46258 | F18: HM_14518_APC.jpeg | G18: August | H18: Dona Hapsari
A19: 8 | B19: 14507 | C19: HM | D19: Diterima | E19: 46265 | F19: HM_14507_APC.jpeg | G19: August | H19: Wiwik Setyaningsih
A20: 9 | B20: 15423 | C20: HM | D20: Diterima | E20: 46269 | F20: HM_15423_APC.jpeg | G20: September | H20: Rusnoto Susanto
A21: 10 | B21: 14604 | C21: HM | D21: Diterima | E21: 46267 | F21: HM_14604_APC.jpeg | G21: September | H21: Prasetyo Adi Wisnu
A22: 11 | B22: 14348 | C22: HM | D22: DIterima | E22: 46175 | G22: July | H22: Indarti

Sheet KPI_3_Enhancing OJS
A1: KPI 3: Enhancing OJS Website 7 Jurnal RTT
A2: Bobot: 7.5% | Target: 50,00 - 74,99
A4: Capaian Saat Ini (Otomatis): | B4: 0 | C4: <-- Ketik manual persentase/capaian di sini
A5: Skor Saat Ini (1-6) (Otomatis): | B5: 0 | C5: <-- Ketik manual skor pencapaian (1-6) di sini
A7: Score 1 | B7: Score 2 | C7: Score 3 | D7: Score 4 | E7: Score 5 | F7: Score 6
A8: 0,00 - 9,99 | B8: 10,00 - 24,99 | C8: 25,00 - 49,99 | D8: 50,00 - 74,99 | E8: 75,00 - 99,99 | F8: 100,00 - 100,00

Sheet KPI_4_Graphic Abstrac
A1: KPI 4: Penerapan Graphic Abstract pada artikel Binus Journal
A2: Bobot: 5.0% | Target: 50,00 - 59,99
A4: Capaian Saat Ini (Otomatis): | B4: =COUNTA(A12:A200) -> 0 | C4: <-- Angka ini otomatis menghitung jumlah baris data
A5: Skor Saat Ini (1-6) (Otomatis): | B5: 0 | C5: <-- Ketik manual skor pencapaian (1-6) di sini
A7: Score 1 | B7: Score 2 | C7: Score 3 | D7: Score 4 | E7: Score 5 | F7: Score 6
A8: 0,00 - 29,99 | B8: 30,00 - 39,99 | C8: 40,00 - 49,99 | D8: 50,00 - 59,99 | E8: 60,00 - 69,99 | F8: 70,00 - 100,00
A10: ⬇️ INPUT DATA REALISASI DI SINI ⬇️
A11: No | B11: Nomor submisi | C11: Nama jurnal | D11: volume | E11: issue | F11: judul | G11: penulis | H11: Gambar abstract | I11: Link | J11: Month

Sheet KPI_5_Writing Competi
A1: KPI 5: Implementation of Scholarly Article Writing Competition
A2: Bobot: 10.0% | Target: ≥ 30 participants
A4: Capaian Saat Ini (Otomatis): | B4: =COUNTA(A12:A200) -> 0 | C4: <-- Angka ini otomatis menghitung jumlah baris data
A5: Skor Saat Ini (1-6) (Otomatis): | B5: 0 | C5: <-- Ketik manual skor pencapaian (1-6) di sini
A7: Score 1 | B7: Score 2 | C7: Score 3 | D7: Score 4 | E7: Score 5 | F7: Score 6
A8: 0.00 - 0.00 | B8: Competition conducted | C8: ≥ 20 participants | D8: ≥ 30 participants | E8: ≥ 40 participants | F8: ≥50 participants and winning artices submit to Binus Journal
A10: ⬇️ INPUT DATA REALISASI DI SINI ⬇️
A11: Nomor Submisi | B11: Nama Jurnal | C11: Judul | D11: Nama Penulis | E11: Evident | F11: Month

Sheet KPI_6_Student Comment
A1: KPI 6: Student Commentary on Journal Binus
A2: Bobot: 7.5% | Target: 50,00 - 59,00
A4: Capaian Saat Ini (Otomatis): | B4: 0 | C4: <-- Ketik manual persentase/capaian di sini
A5: Skor Saat Ini (1-6) (Otomatis): | B5: 0 | C5: <-- Ketik manual skor pencapaian (1-6) di sini
A7: Score 1 | B7: Score 2 | C7: Score 3 | D7: Score 4 | E7: Score 5 | F7: Score 6
A8: 0,00 - 20,00 | B8: 21,00 - 35,00 | C8: 36,00 - 49,00 | D8: 50,00 - 59,00 | E8: 60,00 - 69,00 | F8: 70,00 - 100,00

Sheet KPI_7_ICOBAR
A1: KPI 7: Support Binus Joint International Conference (ICOBAR)
A2: Bobot: 10.0% | Target: 95.00 - 100.00% paper
A4: Capaian Saat Ini (Otomatis): | B4: 0 | C4: <-- Ketik manual persentase/capaian di sini
A5: Skor Saat Ini (1-6) (Otomatis): | B5: 0 | C5: <-- Ketik manual skor pencapaian (1-6) di sini
A7: Score 1 | B7: Score 2 | C7: Score 3 | D7: Score 4 | E7: Score 5 | F7: Score 6
A8: 0.00 - 84.99% paper | B8: 85.00 - 89.99% paper | C8: 90.00 - 94.99% paper | D8: 95.00 - 100.00% paper | E8: Skor 4 + rata-rata selesai H-2 deadline | F8: Skor 4 + rata-rata selesai H-1 deadline

Sheet KPI_8_Editing article
A1: KPI 8: Editing article
A2: Bobot: 15.0% | Target: 4,00 - 4,00
A4: Capaian Saat Ini (Otomatis): | B4: =IFERROR(AVERAGE(N12:N200), 0) -> 0.215625
A5: Skor Saat Ini (1-6) (Otomatis): | B5: =IF(COUNTA(N12:N200)=0, 0, IF(B4<=2, 6, IF(B4<=3, 5, IF(B4<=4, 4, IF(B4<=10, 2, IF(B4<=100, 1, 0)))))) -> 6
A7: Score 1 | B7: Score 2 | C7: Score 3 | D7: Score 4 | E7: Score 5 | F7: Score 6
A8: 11,00 - 100,00 | B8: 5,00 - 10,00 | C8: - | D8: 4,00 - 4,00 | E8: 3,00 - 3,00 | F8: 0,00 - 2,00
A10: ⬇️ INPUT DATA REALISASI DI SINI ⬇️
A11: NOMOR | B11: AFILIASI | C11: Nama Penulis | D11: JUDUL | E11: JURNAL | F11: EDISI | G11: MULAI EDIT | H11: SELESAI EDIT | I11: JAM 1 | J11: JAM 2 | K11: JAM 3 | L11: JAM … | M11: TOTAL | N11: HARI | O11: Month
A12: 14444 | B12: Unsoed | C12: Rosdiana Puspita Sari | D12: POLITICAL PRAGMEMES ON BILLBOARDS IN INDONESIA’S 2024 ELECTION | E12: LC | F12: 20.1 | G12: 46210 | H12: 46212 | I12: 3 | J12: 3 | K12: 3 | L12: 0 | M12: =SUM(I12,J12,K12,L12) -> 9 | N12: =SUM(M12/8) -> 1.125 | O12: July
A13: 14493 | B13: Universitas Tanjungpura | C13: Aulia Rachma Pratiwi; Merry Andriani | D13: Basilectal Variations And Their Function Among Indonesian K-Pop Fans On X | E13: LC | F13: 20.1 | G13: 46211 | H13: 10 | I13: 3 | J13: 2 | K13: 3 | L13: 0 | M13: =SUM(I13,J13,K13,L13) -> 8 | N13: =SUM(M13/8) -> 1 | O13: July
A14: 14584 | B14: UGM | C14: Hidayah Nuril Phasa; Merry Andriani | D14: INTERNAL LANGUAGE SHIFT IN JAVANESE SPEECH LEVELS: DIGITAL INFLUENCE AMONG GENERATION ALPHA IN BOJONEGORO | E14: LC | F14: 20.1 | G14: 46210 | H14: 46212 | I14: 3 | J14: 3 | K14: 3 | L14: 0 | M14: =SUM(I14,J14,K14,L14) -> 9 | N14: =SUM(M14/8) -> 1.125 | O14: July
A15: 14626 | B15: UNIS | C15: Irmala Sukendra; Riska Khumairoh | D15: Conversational Implicature in the Discourse of Digital Hate Towards BTS on X | E15: LC | F15: 20.1 | G15: 46209 | H15: 46212 | I15: 3 | J15: 1 | K15: 2 | L15: 0 | M15: =SUM(I15,J15,K15,L15) -> 6 | N15: =SUM(M15/8) -> 0.75 | O15: July
E16: CT | I16: 2 | M16: =SUM(I16,J16,K16,L16) -> 2 | N16: =SUM(M16/8) -> 0.25
A17: 14334 | B17: UNEJ; UNUSIA; ASIA Univeristy (Taiwan) | C17: Ni Luh Ayu Sukmawati; Fina Zahra; Sheila Wijayanti; Yinghuei Chen | D17: Hegemony in Horror: Examining the Constructs of Fear in Siksa Kubur (2024) | E17: HM | F17: 17.2 | G17: 46230 | H17: 46230 | I17: 4 | J17: 0 | K17: 0 | L17: 0 | M17: =SUM(I17,J17,K17,L17) -> 4 | N17: =SUM(M17/8) -> 0.5 | O17: July
A18: 14404 | B18: Universitas Bhinneka PGRI Tulungagung; UIN Sayyid Ali Rahmatullah | C18: Hikmah Eva Trisnantari; Prim Masrokan Mutohar; Zahrotunnisa Siswahyuningsih | D18: The Reconstruction of Urban Community Nationalism Based on Local Wisdom of Tirakatan | E18: HM | F18: 17.2 | G18: 46232 | H18: 46232 | I18: 3 | J18: 0 | K18: 0 | L18: 0 | M18: =SUM(I18,J18,K18,L18) -> 3 | N18: =SUM(M18/8) -> 0.375 | O18: July
A19: 14679 | B19: ISI Surakarta | C19: Fajar Aji; Ranang Agung Sugihartono | D19: Camera Movement Style in Indonesian OTT Originals: Two-Case Using Nielsen’s Five Functions | E19: HM | F19: 17.2 | G19: 46234 | H19: 46234 | I19: 4 | J19: 0 | K19: 0 | L19: 0 | M19: =SUM(I19,J19,K19,L19) -> 4 | N19: =SUM(M19/8) -> 0.5 | O19: July
A20: 14723 | B20: ISI Surakarta | C20: Sri Wahyuni Muhtar; Aris Setiawan; Budi Setiyono | D20: Cultural Appropriation as Local Identity: The Case of Dangdut Makassar | E20: HM | F20: 17.2 | G20: 46238 | H20: 46268 | I20: 2 | J20: 1 | K20: 0 | L20: 0 | M20: =SUM(I20,J20,K20,L20) -> 3 | N20: =SUM(M20/8) -> 0.375 | O20: August
A21: 14900 | B21: Columbia University | C21: Putri Maharani | D21: Unseen Drivers of Climate Change and Early Marriage Narratives in Coastal Jakarta | E21: HM | F21: 17.2 | G21: 46238 | H21: 46268 | I21: 2 | J21: 1 | K21: 0 | L21: 0 | M21: =SUM(I21,J21,K21,L21) -> 3 | N21: =SUM(M21/8) -> 0.375 | O21: August
A22: 13890 | B22: SBM-ITB | C22: Panji Mukadis; Mustika Purwanegara; Atik Aprianingsih | D22: Perceptions of Indonesian Movies among Gen-Z: A Sentiment Analysis Approach | E22: HM | F22: 17.2 | G22: 46239 | H22: 46240 | I22: 2 | J22: 2 | K22: 0 | L22: 0 | M22: =SUM(I22,J22,K22,L22) -> 4 | N22: =SUM(M22/8) -> 0.5 | O22: August
A23: 13880 | B23: Calvin Institute of Technology | C23: Erwin Anggadjaja; Matthew Amadeus | D23: Campus Surveillance System with HTTP Communication Using Animaloid Robots | E23: CT | F23: 17.2 | G23: 46225 | H23: 46240 | I23: 2 | J23: 1 | M23: =SUM(I23,J23,K23,L23) -> 3 | N23: =SUM(M23/8) -> 0.375 | O23: July
A24: 13886 | B24: UNTAN | C24: Zuleha Zuleha; Nur'ainul Huda; Nurfitri Imro'ah; Gita Fitriyana | D24: GSTAR (1,1) MODELING WITH QUEEN CONTIGUITY MATRIX FOR FIRE RADIATIVE POWER ANALYSIS | E24: CT | F24: 17.2 | G24: 46241 | I24: 2 | M24: =SUM(I24,J24,K24,L24) -> 2 | N24: =SUM(M24/8) -> 0.25 | O24: August
A25: 14633 | B25: Universitas Negeri Semarang; Ismaili Institutions for Canada | C25: Rima Vien Permata Hartanto; Maram Taher; Petriscia Kusuma Wardani | D25: Gender Blindness and Legal Recognition: Feminist Critique of Indonesia’s Law 7/2016 | E25: HM | F25: 17.2 | G25: 46268 | H25: 46268 | I25: 3 | J25: 0 | K25: 0 | L25: 0 | M25: =SUM(I25,J25,K25,L25) -> 3 | N25: =SUM(M25/8) -> 0.375 | O25: September
A26: 14900 | C26: Putri Maharani | D26: Unseen Drivers of Climate Change and Early Marriage Narratives in Coastal Jakarta | E26: HM | F26: 17.2 | G26: 46268 | H26: 46268 | I26: 2 | J26: 0 | K26: 0 | L26: 0 | M26: =SUM(I26,J26,K26,L26) -> 2 | N26: =SUM(M26/8) -> 0.25 | O26: September
A27: 14254 | B27: IPB University | C27: Harry Dhika; Agus Buono; Shelvie Nidya Neyman | D27: PREDICTION OF TRANSPORTATION-INDUCED PHYSIOLOGICAL STRESS IN CATTLE USING AN ARTIFICIAL NEURAL NETWORK | E27: CT | F27: 17.2 | G27: 46268 | I27: 2 | M27: =SUM(I27,J27,K27,L27) -> 2 | N27: =SUM(M27/8) -> 0.25 | O27: September
A28: 14687 | B28: BINUS University | C28: Rahmat Daryono; Christian Harito | D28: An Integrated BSC–Fuzzy DEMATEL–ANP to Continuous Improvement in Electronic Manufacturing | E28: CT | F28: 17.2 | G28: 46276 | I28: 2 | M28: =SUM(I28,J28,K28,L28) -> 2 | N28: =SUM(M28/8) -> 0.25 | O28: September
M29: =SUM(I29,J29,K29,L29) -> 0 | N29: =SUM(M29/8) -> 0
M30: =SUM(I30,J30,K30,L30) -> 0 | N30: =SUM(M30/8) -> 0
M31: =SUM(I31,J31,K31,L31) -> 0 | N31: =SUM(M31/8) -> 0
M32: =SUM(I32,J32,K32,L32) -> 0 | N32: =SUM(M32/8) -> 0
M33: =SUM(I33,J33,K33,L33) -> 0 | N33: =SUM(M33/8) -> 0
M34: =SUM(I34,J34,K34,L34) -> 0 | N34: =SUM(M34/8) -> 0
M35: =SUM(I35,J35,K35,L35) -> 0 | N35: =SUM(M35/8) -> 0
M36: =SUM(I36,J36,K36,L36) -> 0 | N36: =SUM(M36/8) -> 0
M37: =SUM(I37,J37,K37,L37) -> 0 | N37: =SUM(M37/8) -> 0
M38: =SUM(I38,J38,K38,L38) -> 0 | N38: =SUM(M38/8) -> 0
M39: =SUM(I39,J39,K39,L39) -> 0 | N39: =SUM(M39/8) -> 0
M40: =SUM(I40,J40,K40,L40) -> 0 | N40: =SUM(M40/8) -> 0
... M51: =SUM(I51,J51,K51,L51) -> 0 | N51: =SUM(M51/8) -> 0

Sheet KPI_9_Review Format
A1: KPI 9: Review Format Article
A2: Bobot: 10.0% | Target: 2,00 - 2,99
A4: Capaian Saat Ini (Otomatis): | B4: =IFERROR(AVERAGE(N12:N200), 0) -> 0.043320106
A5: Skor Saat Ini (1-6) (Otomatis): | B5: =IF(COUNTA(N12:N200)=0, 0, IF(B4<=0.99, 6, IF(B4<=1.99, 5, IF(B4<=2.99, 4, IF(B4<=3.99, 3, IF(B4<=4.99, 2, 1)))))) -> 6
A7: Score 1 | B7: Score 2 | C7: Score 3 | D7: Score 4 | E7: Score 5 | F7: Score 6
A8: 5,00 - 100,00 | B8: 4,00 - 4,99 | C8: 3,00 - 3,99 | D8: 2,00 - 2,99 | E8: 1,00 - 1,99 | F8: 0,00 - 0,99
A10: ⬇️ INPUT DATA REALISASI DI SINI ⬇️
A11: NOMOR | B11: AFILIASI | C11: Nama Penulis | D11: JUDUL | E11: JURNAL | F11: EDISI | G11: MULAI EDIT | H11: SELESAI EDIT | I11: JAM 1 | J11: JAM 2 | K11: JAM 3 | L11: JAM … | M11: TOTAL | N11: HARI | O11: Month
A12: 15455 | B12: Universitas Muhammadiyah Sidoarjo | C12: Evy Sulistianingsih | D12: Optimization of SRI-KEHATI Indexed Stock Portfolios with Extreme Gradient Boosting and Mean-Variance Efficient Portfolio | E12: CT | F12: 17.1 | G12: 46209 | H12: 46217 | I12: 3 | J12: 2 | K12: 1 | L12: 0 | M12: =SUM(I12+J12+K12+L12) -> 6 | N12: =SUM(M12/8) -> 0.75 | O12: July
A13: 15615 | B13: UIII | C13: Fath Yusava Arden; Settings Mukhammad Andri Setiawan | D13: Hybrid Framework for Token-Efficient LLM-Based Running Analysis | E13: CT | F13: 17.1 | G13: 46212 | H13: 46212 | I13: 4 | J13: 0 | K13: 0 | L13: 0 | M13: =SUM(I13+J13+K13+L13) -> 4 | N13: =SUM(M13/8) -> 0.5 | O13: July
A14: 14976 | B14: BINUS | C14: Abhiseka Wisnu Wiyarta; Christian Harito | D14: Safety Culture’s Mediating Role Between 5S Implementation and Employee Performance in Petrochemical | E14: CT | F14: 17.1 | G14: 46212 | H14: 46212 | I14: 3 | J14: 0 | K14: 0 | L14: 0 | M14: =SUM(I14+J14+K14+L14) -> 3 | N14: =SUM(M14/8) -> 0.375 | O14: July
A15: 15665 | B15: IPB | C15: Sabrina; Mochamad Tito Julianto; Mohamad Khoirun Najib | D15: PROBABILISTIC TOPIC MODELING AND SENTIMENT CLASSIFICATION OF WARDAH GLASTING LIQUID LIP REVIEWS | E15: CT | F15: 17.1 | G15: 46213 | H15: 46213 | I15: 4 | J15: 0 | K15: 0 | L15: 0 | M15: =SUM(I15+J15+K15+L15) -> 4 | N15: =SUM(M15/8) -> 0.5 | O15: July
A16: 15953 | B16: Universitas Satya Negara Indonesia; Universitas Budi Luhur ; Universitas Indraprasta PGRI; Universitas Budi Luhur; Washington State University (US) | C16: Sukarno Bahat Nauli; Billy Marentek; Rudi Prasetya; Yan Everhard Riwurohi; Martinus Damitutsa Kurnia Dewa | D16: AI Ethics Framework Model for Information Technology System Development | E16: CT | F16: 17.1 | G16: 46216 | H16: 46217 | I16: 2 | J16: 2 | K16: 0 | L16: 0 | M16: =SUM(I16+J16+K16+L16) -> 4 | N16: =SUM(M16/8) -> 0.5 | O16: July
A17: 15375 | B17: BINUS | C17: Fransisca Tiur Basaria; Kenny Jeremia Zondag Ginting | D17: An Integrated Data-Driven Framework For B2b Customer Segmentation and Campaign Optimization Using Clustering, Forecasting, And Simulation | E17: CT | F17: 17.1 | G17: 46217 | H17: 46217 | I17: 2 | J17: 0 | K17: 0 | L17: 0 | M17: =SUM(I17+J17+K17+L17) -> 2 | N17: =SUM(M17/8) -> 0.25 | O17: July
A18: 15673 | B18: BINUS | C18: Asysta Amalia Pasaribu;I Gusti Agung Anom Yudistira; Hanis Amalia Saputri | D18: Improving Volatility Forecasting Commodity and Financial Markets Using GARCH and SVR Models | E18: CT | F18: 17.1 | G18: 46217 | H18: 46217 | I18: 1 | J18: 0 | K18: 0 | L18: 0 | M18: =SUM(I18+J18+K18+L18) -> 1 | N18: =SUM(M18/8) -> 0.125 | O18: July
A19: 15571 | B19: BINUS | C19: Adriana Sinta Anarita; Dr. Sri Rachmayanti S.Sn., M.Ds | D19: Sensory Coexistence: Multisensory Cues and Cultural Experience in Contemporary Hospitality Design | E19: Humaniora | F19: 17.2 | G19: 46218 | H19: 46218 | I19: 1 | J19: 0 | K19: 0 | L19: 0 | M19: =SUM(I19+J19+K19+L19) -> 1 | N19: =SUM(M19/8) -> 0.125 | O19: July
A20: 15689 | B20: BINUS | C20: Asysta Amalia Pasaribu; Neni Nur Laili Ersela Zain | D20: Forecasting Value-at-Risk of GARCH-Copula Models of Bitcoin and Litecoin Cryptocurrency | E20: CT | F20: 17.1 | G20: 46218 | H20: 46235 | I20: 2 | J20: 1 | K20: 0 | L20: 0 | M20: =SUM(I20+J20+K20+L20) -> 3 | N20: =SUM(M20/8) -> 0.375 | O20: July
A21: 14077 | B21: Institut Pertanian Bogor | C21: Ferika Bestati Panjaitan | D21: CONTENT ANALYSIS OF COMMUNITY DIALOGUES: CASE STUDY MUSRENBANG DESA IN BOGOR REGENCY | E21: HM | G21: 46218 | M21: =SUM(I21+J21+K21+L21) -> 0 | N21: =SUM(M21/8) -> 0 | O21: July
A22: 15689 | B22: BINUS | C22: Asysta Amalia Pasaribu;Settings Neni Nur Laili Ersela Zain | D22: Forecasting Value-at-Risk of GARCH-Copula Models of Bitcoin and Litecoin Cryptocurrency | E22: CT | G22: 46219 | H22: 46235 | I22: 2 | J22: 1 | K22: 0 | L22: 0 | M22: =SUM(I22+J22+K22+L22) -> 3 | N22: =SUM(M22/8) -> 0.375 | O22: July
A23: 15846 | B23: Mercubuana Yogya; UBM; BINUS | C23: Settings Putry Wahyu Setyaningsih; Settings Ozmar Azhari; Septian Eka Ady Buananta | D23: EXPLORING USER-CENTRIC GOVERNANCE THROUGH USER EXPERIENCE EVALUATION OF PUBLIC SERVICE WEBSITES | E23: CT | G23: 46219 | H23: 46232 | I23: 1 | J23: 1 | M23: =SUM(I23+J23+K23+L23) -> 2 | N23: =SUM(M23/8) -> 0.25 | O23: July
A24: 15853 | B24: Institut Teknologi dan Bisnis Indonesia; Universiti Malaysia Pahang (Malay) | C24: Roberto Kaban; David JM Sembiring; Jamaludin Bin Sallim | D24: NAIR: A Noise-Aware Ranking Model for Robust Information Retrieval under Noisy Query Conditions | E24: CT | G24: 46223 | H24: 46235 | I24: 2 | J24: 1 | M24: =SUM(I24+J24+K24+L24) -> 3 | N24: =SUM(M24/8) -> 0.375 | O24: July
A25: Q3 | M25: =SUM(I25+J25+K25+L25) -> 0 | N25: =SUM(M25/8) -> 0
A26: 15135 | B26: UNTAN | C26: Said Basalim | D26: Urban Pavement Performance Modeling Using Smartphone-Based IRI and Ordered Logit | E26: CT | G26: 46226 | H26: 46235 | I26: 2 | J26: 1 | M26: =SUM(I26+J26+K26+L26) -> 3 | N26: =SUM(M26/8) -> 0.375 | O26: July
A27: 15933 | B27: BINUS | C27: Saut Horas Ramses Samosir; Tuga Mauritsius | D27: HYBRID AHP-TOPSIS MODEL FOR ONLINE RECRUITMENT PLATFORMS SELECTION IN INDONESIAN | E27: CT | G27: 46226 | H27: 46241 | I27: 2 | J27: 1 | K27: 0 | L27: 0 | M27: =SUM(I27+J27+K27+L27) -> 3 | N27: =SUM(M27/8) -> 0.375 | O27: July
A28: 16133 | B28: UGM | C28: Fadilah Tsalsabillah Makarawo; Adi Sutrisno | D28: Translation Equivalence and Legal Adaptation: A Semantic Analysis of Defined Terminology in the Indonesia–UAE CEPA (2022) | E28: LC | G28: 46238 | I28: 2 | M28: =SUM(I28+J28+K28+L28) -> 2 | N28: =SUM(M28/8) -> 0.25 | O28: August
A29: 16237 | B29: UNJ | C29: Ayu Trihardini; Hermina Sutami; Munif Yusuf | D29: Linearity of Chinese Spatial Prepositional Phrases: A Cognitive Linguistics Study | E29: LC | G29: 46239 | I29: 1 | J29: 1 | M29: =SUM(I29+J29+K29+L29) -> 2 | N29: =SUM(M29/8) -> 0.25 | O29: August
A30: 16284 | B30: UIN Sunan Ampel | C30: Muzakki Abdurrahman | D30: BEYOND HUMAN LITERACY: LANGUAGE, LITERATURE, AND MEANING-MAKING IN GENERATIVE AI | E30: LC | G30: 46239 | I30: 1.5 | M30: =SUM(I30+J30+K30+L30) -> 1.5 | N30: =SUM(M30/8) -> 0.1875 | O30: August
A31: 14941 | B31: UNSOED | C31: Syahrul Fadholi Gumelar | D31: Comparison of YOLOv8 Detection Model Size for Periapical Periodontitis Detection Based on Dental Radiograph Dataset | E31: CT | G31: 46239 | H31: 46239 | I31: 1 | J31: 0 | K31: 0 | L31: 0 | M31: =SUM(I31+J31+K31+L31) -> 1 | N31: =SUM(M31/8) -> 0.125 | O31: August
A32: 15994 | B32: UNUD | C32: Anak Agung Ngurah Wisnu Wardana | D32: AI-BASED DIGITAL TECHNOLOGY FOR MENTAL HEALTH SELF-SCREENING IN PRIMARY HEALTH CARE | E32: CT | G32: 46241 | H32: 46268 | I32: 2 | J32: 1 | M32: =SUM(I32+J32+K32+L32) -> 3 | N32: =SUM(M32/8) -> 0.375 | O32: August
A33: 16220 | B33: UPN JATIM | C33: Rizky; Aprinia; Budy; Heliza; Budi; Saefurrohman; Imam; Faris | D33: Multi-Feature Classification of IMDb Movie Reviews with Stacking Ensemble and SHAP Interpretation | E33: CT | G33: 46246 | I33: 2 | M33: =SUM(I33+J33+K33+L33) -> 2 | N33: =SUM(M33/8) -> 0.25 | O33: August
A34: 16231 | B34: UNESA | C34: Daffa Ahmad Pangreksa; Halilatunnisa; Naura Kanaya Putri Masruri; Ibnu Febry Kurniawan | D34: TalentTrack: A Data Warehouse with Zero-Shot Skill Extraction for Labor Market Forecasting | E34: CT | G34: 46246 | I34: 2 | M34: =SUM(I34+J34+K34+L34) -> 2 | N34: =SUM(M34/8) -> 0.25 | O34: August
A35: 16239 | B35: UPI | C35: Arditya Baskara Mahbubi; Dewi Indriati; Muhammad Rizalul Wahid | D35: Edge Deployed Class Incremental Learning for Adaptive Electronic Component Sorting in IIoT Based HMLV Manufacturing IIoT Based HMLV Manufacturing: An Empirical Evaluation | E35: CT | G35: 46246 | I35: 1 | M35: =SUM(I35+J35+K35+L35) -> 1 | N35: =SUM(M35/8) -> 0.125 | O35: August
A36: 16030 | B36: UNISlA; Institut Teknologi Kalimantan; Universitas Nahdlatul Ulama Sunan Giri; Universitas Mulawarman | C36: Diah Ayu Novitasari; Muchammad Chandra Cahyo Utomo; Ika Purnamasari; Denny Nurdiansyah; Miftakhul Khasanah | D36: Seasonal Forecasting Stability and Accuracy for East Java Rice Harvest Area Prediction | E36: CT | G36: 46258 | H36: 46268 | I36: 1 | J36: 1 | M36: =SUM(I36+J36+K36+L36) -> 2 | N36: =SUM(M36/8) -> 0.25 | O36: August
A37: 16078 | B37: Politeknik Negeri Jember; University of Szeged (Hungary) | C37: Khafidurrohman Agustianto; Saiful Bukhori; Mas’ud Hermansyah; Adriadi Novawan | D37: Detecting Anxiety Onset in Metacognitive Monitoring Using Temporal Eye-Tracking and Machine Learning | E37: CT | G37: 46258 | I37: 1 | M37: =SUM(I37+J37+K37+L37) -> 1 | N37: =SUM(M37/8) -> 0.125 | O37: August
A38: 16345 | B38: Ahmad Dahlan University; University of Mosul | C38: Fidya Raihana Salsabila; Sugiyarto Surono; Joko Purwadi; Kais Ismail Ibraheem; Aris Thorbirin | D38: CONSISTENCY AND STABILITY OF MULTI-METHOD EXPLAINABLE AI IN XGBOOST MANUFACTURING DEFECT PREDICTION | E38: CT | G38: 46268 | H38: 46274 | I38: 1 | J38: 1 | M38: =SUM(I38+J38+K38+L38) -> 2 | N38: =SUM(M38/8) -> 0.25 | O38: September
A39: 16414 | B39: Universitas HKBP Nommensen | C39: elza leyli saragih | D39: HIERARCHICAL PATTERNS OF LINGUISTIC POLITENESS IN COMMERCIAL TRANSACTIONS AMONG THE TOBA BATAK COMMUNITY | E39: LC | G39: 46268 | I39: 1 | M39: =SUM(I39+J39+K39+L39) -> 1 | N39: =SUM(M39/8) -> 0.125 | O39: September
A40: 15962 | B40: BINUS | C40: Alief Fikrul Hakam El Jauhari; Yulyani Arifin | D40: Strengthening Information Security Governance In The Construction Sector Using The Octave Allegro Method And ISO/IEC 27001:2022 | E40: CT | G40: 46268 | I40: 1 | M40: =SUM(I40+J40+K40+L40) -> 1 | N40: =SUM(M40/8) -> 0.125 | O40: Sepember
A41: 16348 | B41: Universitas Islam Negeri Jurai Siwo Lampung | C41: Ahmad Madkur; Aria Septi Anggaira | D41: WHEN AI ANSWERS FOR THEM: A TRANSLANGUAGING APPROACH TO RECLAIMING EFL LEARNERS’ GRAMMAR COMPETENCE | E41: LC | G41: 46274 | I41: 1 | M41: =SUM(I41+J41+K41+L41) -> 1 | N41: =SUM(M41/8) -> 0.125 | O41: September
A42: 16334 | B42: Institut Teknologi Del | C42: Rentauli Mariah Silalahi | D42: ChatGPT Assistance in Indonesian Argumentative Writing: Effects Across Dimensions and Initial Performance | E42: LC | G42: 46274 | I42: 1 | M42: =SUM(I42+J42+K42+L42) -> 1 | N42: =SUM(M42/8) -> 0.125 | O42: September
M43: =SUM(I43+J43+K43+L43) -> 0 | N43: =SUM(M43/8) -> 0
...

Sheet KPI_10_Waktu review
A1: KPI 10: Waktu review artikel
A2: Bobot: 10.0% | Target: 6,00 - 7,00
A4: Capaian Saat Ini (Otomatis): | B4: =IFERROR(AVERAGE(F12:F200), 0) -> 1.8857143
A5: Skor Saat Ini (1-6) (Otomatis): | B5: =IF(COUNTA(F12:F200)=0, 0, IF(B4<=3, 6, IF(B4<=5, 5, IF(B4<=7, 4, IF(B4<=9, 3, IF(B4<=11, 2, 1)))))) -> 6
A7: Score 1 | B7: Score 2 | C7: Score 3 | D7: Score 4 | E7: Score 5 | F7: Score 6
A8: 12,00 - 100,00 | B8: 10,00 - 11,00 | C8: 8,00 - 9,00 | D8: 6,00 - 7,00 | E8: 4,00 - 5,00 | F8: 0,00 - 3,00
A10: ⬇️ INPUT DATA REALISASI DI SINI ⬇️
A11: No | B11: Afiliasi Penulis | C11: Judul | D11: Tanggal Mulai Proses Review | E11: Tanggal Hasil Review Konten Keluar | F11: Minggu | G11: Month
A12: 1 | B12: BINUS | C12: Sensory Coexistence: Multisensory Cues and Cultural Experience in Contemporary Hospitality Design | D12: 46218 | F12: =IF(OR(ISBLANK(D12), ISBLANK(E12)), "", (E12-D12)/7) | G12: July
A13: 2 | B13: Universitas Ciputra; The National University of Singapore | C13: PROMOTING SOCIAL COHESION THROUGH INTERCULTURAL COMMUNICATION: AN INTERETHNIC UNCERTAINTY REDUCTION IN A YOUTH CAMP | D13: 46218 | F13: =IF(OR(ISBLANK(D13), ISBLANK(E13)), "", (E13-D13)/7) | G13: July
A14: 3 | B14: IPB University | C14: CONTENT ANALYSIS OF COMMUNITY DIALOGUES: CASE STUDY MUSRENBANG DESA IN BOGOR REGENCY | D14: 46218 | E14: 46261 | F14: =IF(OR(ISBLANK(D14), ISBLANK(E14)), "", (E14-D14)/7) -> 6.1428571 | G14: July
A15: 4 | B15: Universitas Katolik Indonesia Santu Paulus Ruteng | C15: ILLOCUTIONARY ACTS IN THE ROKO MOLAS POCO RITUAL IN STRENGTHENING LOCAL CULTURE-BASED PRAGMATICS | D15: 46218 | F15: =IF(OR(ISBLANK(D15), ISBLANK(E15)), "", (E15-D15)/7) | G15: July
A16: 5 | B16: UNESA; niversiti Pendidikan Sultan Idris (Malaysia) | C16: THE PSYCHOLOGICAL IMPACT OF TRANSFORMING FORMER DOLLY RED LIGHT DISTRICT THROUGH CREATIVE BATIK INDUSTRY | D16: 46218 | F16: =IF(OR(ISBLANK(D16), ISBLANK(E16)), "", (E16-D16)/7) | G16: July
A17: 6 | B17: UNSOED; Tianjin University (China) | C17: Representation of Chinese Identity through Symbols and Linguistic Signs in the Chinatowns of Semarang and Yogyakarta | D17: 46218 | E17: 46237 | F17: =IF(OR(ISBLANK(D17), ISBLANK(E17)), "", (E17-D17)/7) -> 2.7142857 | G17: July
A18: 7 | B18: Universitas Sarjanawiyata Tamansiswa; BINUS; UNY | C18: UPCYCLED MINDI WOOD BAG REDESIGN BASED AFF APPROACH: A POPULAR CULTURE PERSPECTIVE | D18: 46218 | F18: =IF(OR(ISBLANK(D18), ISBLANK(E18)), "", (E18-D18)/7) | G18: July
A19: 8 | B19: Universitas Ciputra; National University of Singapore (NUS) | C19: PROMOTING SOCIAL COHESION THROUGH INTERCULTURAL COMMUNICATION: AN INTERETHNIC UNCERTAINTY REDUCTION IN A YOUTH CAMP | D19: 46218 | F19: =IF(OR(ISBLANK(D19), ISBLANK(E19)), "", (E19-D19)/7) | G19: July
A20: 9 | B20: BINUS | C20: URBAN IDENTITY OF JAKARTA STREET VENDORS' FURNITURE BASED ON CULTURAL ANALYSIS AND VISUAL REPRESENTATION | D20: 46218 | F20: =IF(OR(ISBLANK(D20), ISBLANK(E20)), "", (E20-D20)/7) | G20: July
A21: 10 | B21: UNNES | C21: ETHNOPEDAGOGY AS COMMUNITY-BASED CRAFTS EDUCATION IN THE STONE CARVING ARTISANS OF MUNTILAN | D21: 46218 | F21: =IF(OR(ISBLANK(D21), ISBLANK(E21)), "", (E21-D21)/7) | G21: July
A22: 11 | B22: Institut Agama Islam Negeri Kerinci | C22: Incung Script in Transition: A Clifford Geertzian Analysis of Functional and Symbolic Change in Kerinci | D22: 46218 | F22: =IF(OR(ISBLANK(D22), ISBLANK(E22)), "", (E22-D22)/7) | G22: July
A23: 12 | B23: BINUS | C23: Safety Culture’s Mediating Role Between 5S Implementation and Employee Performance in Petrochemical | D23: 46212 | E23: 46220 | F23: =IF(OR(ISBLANK(D23), ISBLANK(E23)), "", (E23-D23)/7) -> 1.1428571 | G23: July
A24: 13 | B24: Mulwarman University | C24: The Discourse of Authenticity and Identity in the Dayak Sapeq Music Community | D24: 46220 | F24: =IF(OR(ISBLANK(D24), ISBLANK(E24)), "", (E24-D24)/7) | G24: July
A25: 14 | B25: UII | C25: Ruqyah as a Prophetic Mission: Analyzing The Religious Voice of The Horror Film Qodrat | D25: 46221 | F25: =IF(OR(ISBLANK(D25), ISBLANK(E25)), "", (E25-D25)/7) | G25: July
A26: 15 | B26: UNY | C26: CIBEBER DUCK SATAY AS A COMMUNITY IDENTITY AND INTANGIBLE CULTURAL HERITAGE OF CILEGON CITY | F26: =IF(OR(ISBLANK(D26), ISBLANK(E26)), "", (E26-D26)/7)
A27: 16 | B27: UNS | C27: Tumpeng as a Cosmogram of Material Prayer in Javanese Hermeneutic Epistemology | D27: 46221 | F27: =IF(OR(ISBLANK(D27), ISBLANK(E27)), "", (E27-D27)/7) | G27: July
A28: 17 | B28: UNY | C28: Semiotics of Roland Barthes in The Caos Bekti Tradition of Surakarta Hadiningrat Court: A Case Study of Astanaluhur Paremono | D28: 46223 | F28: =IF(OR(ISBLANK(D28), ISBLANK(E28)), "", (E28-D28)/7) | G28: July
A29: 18 | B29: UPI | C29: Project-Based Dance Education as Cultural Negotiation: Constructing Indonesian Identity in a Diasporic School Context | D29: 46223 | F29: =IF(OR(ISBLANK(D29), ISBLANK(E29)), "", (E29-D29)/7) | G29: July
A30: 19 | B30: Universitas Ekasakti | C30: SLANG IN THE END OF THE F***ING WORLD FILM SERIES: A SOCIOLINGUISTIC ANALYSIS | D30: 46223 | E30: 46245 | F30: =IF(OR(ISBLANK(D30), ISBLANK(E30)), "", (E30-D30)/7) -> 3.1428571 | G30: July
A31: 20 | B31: UNHAS | C31: Myth and Meaning in the Naming of Marine Ornamental Fish in Coastal South Sulawesi | D31: 46223 | F31: =IF(OR(ISBLANK(D31), ISBLANK(E31)), "", (E31-D31)/7) | G31: July
A32: 21 | B32: UNSOED | C32: Group Communication and Multimodal Media in the Empowerment of Inclusive Art Studio Communities | D32: 46223 | F32: =IF(OR(ISBLANK(D32), ISBLANK(E32)), "", (E32-D32)/7) | G32: July
A33: 22 | B33: UNUGIRI | C33: Clustering Of Character Strengthening Of Victim Groups Using The K-Means Method In The Context Of Suicide Prevention In East Java And Central Java | D33: 46223 | F33: =IF(OR(ISBLANK(D33), ISBLANK(E33)), "", (E33-D33)/7) | G33: July
A34: 23 | B34: politeknikbatulicin | C34: Utilization of Predictive Models to Optimize TBM Performance in the Construction of the Jakarta MRT | D34: 46223 | F34: =IF(OR(ISBLANK(D34), ISBLANK(E34)), "", (E34-D34)/7) | G34: July
A35: 24 | B35: BINUS | C35: An Integrated Data-Driven Framework For B2b Customer Segmentation and Campaign Optimization Using Clustering, Forecasting, And Simulation | D35: 46224 | F35: =IF(OR(ISBLANK(D35), ISBLANK(E35)), "", (E35-D35)/7) | G35: July
A36: 25 | B36: State Polytechnic of Malang | C36: Simulation Analysis of Load Force Variation Structure in Manufacturing Process of Jig Fixture for Milling Machining Equipment Made of AISI 1020 Material | D36: 46224 | F36: =IF(OR(ISBLANK(D36), ISBLANK(E36)), "", (E36-D36)/7) | G36: July
A37: 26 | B37: Saint Louis University (PH) | C37: WHEN CHATGPT AND HUMANS TELL STORIES: EXPLORING LEXICAL FEATURES AND NARRATIVE TRANSPORTATION IN MICROFICTION | D37: 46224 | F37: =IF(OR(ISBLANK(D37), ISBLANK(E37)), "", (E37-D37)/7) | G37: July
A38: 27 | B38: Airlangga University | C38: The Effect of Resample Method to Predict Academic Success | D38: 46225 | E38: 46234 | F38: =IF(OR(ISBLANK(D38), ISBLANK(E38)), "", (E38-D38)/7) -> 1.2857143 | G38: July
A39: 28 | B39: National Taiwan University of Science and Technology | C39: Optimized Traffic Object Detection at Intersections with YOLOv4 and YOLOv4 Tiny: Day and Night Analysis | D39: 46230 | F39: =IF(OR(ISBLANK(D39), ISBLANK(E39)), "", (E39-D39)/7) | G39: July
A40: 29 | B40: Universitas Indonesia | C40: Scent, Image, Text: Visual–Verbal Alignment in Luxury Perfume Campaigns on Instagram | D40: 46238 | E40: 46238 | F40: =IF(OR(ISBLANK(D40), ISBLANK(E40)), "", (E40-D40)/7) -> 0 | G40: August
A41: 30 | B41: Trunojoyo | C41: THE SUSTAINABILITY PERFORMANCE OF BIODIESEL PRODUCTION USING USED COOKING OIL (UCO): A TECHNOLOGY ASSESSMENT | D41: 46239 | E41: 46239 | F41: =IF(OR(ISBLANK(D41), ISBLANK(E41)), "", (E41-D41)/7) -> 0 | G41: August
A42: 31 | B42: Institut Seni Indonesia Yogyakarta | C42: Preventive Conservation of Cassava Paper as an Alternative Writing Media in the Archives Collection of the Sonobudoyo Museum, Yogyakarta, Indonesia | D42: 46240 | F42: =IF(OR(ISBLANK(D42), ISBLANK(E42)), "", (E42-D42)/7) | G42: August
A43: 32 | B43: Universitas Indraprasta PGRI | C43: ECOLOGICAL WORLDVIEWS IN CHILDREN’S STORYBOOKS BY YOUNG AUTHORS | D43: 46245 | F43: =IF(OR(ISBLANK(D43), ISBLANK(E43)), "", (E43-D43)/7) | G43: August
...

Sheet KPI_11_Tugas Khusus
A1: KPI 11: Tugas Khusus
A2: Bobot: 5.0% | Target: Minimum 3 tugas khusus (sesuai validasi VR RTT) diselesaikan
A4: Capaian Saat Ini (Otomatis): | B4: =COUNTA(A12:A200) -> 0 | C4: <-- Angka ini otomatis menghitung jumlah baris data
A5: Skor Saat Ini (1-6) (Otomatis): | B5: 0 | C5: <-- Ketik manual skor pencapaian (1-6) di sini
A7: Score 1 | B7: Score 2 | C7: Score 3 | D7: Score 4 | E7: Score 5 | F7: Score 6
A8: Minimum 1 tugas khusus (sesuai validasi VR RTT) diselesaikan | B8: - | C8: Minimum 2 tugas khusus (sesuai validasi VR RTT) diselesaikan | D8: Minimum 3 tugas khusus (sesuai validasi VR RTT) diselesaikan | E8: Minimum 5 tugas khusus (sesuai validasi VR RTT) diselesaikan | F8: Skor 5 DAN ada bentuk storrytelling dengan hashtag #BinusResearchPoint
A10: ⬇️ INPUT DATA REALISASI DI SINI ⬇️
A11: Nama tugas | B11: tanggal mulai | C11: tanggal selesai | D11: evident | E11: Month
